'Chromosome aberrations in solid tumors.';Traceback (most recent call last):|  File "/home/dmitry/PycharmProjects/VeriFast/./app/Background_tasks.py", line 34, in download_article|    xml_file_text, source = await SearcherObj(doi_or_name)|  File "/home/dmitry/PycharmProjects/VeriFast/./searcher.py", line 68, in __call__|    pmc_parsed = ET.fromstring(pmc_xml)|  File "/home/dmitry/.conda/envs/VeriFast/lib/python3.9/xml/etree/ElementTree.py", line 1347, in XML|    parser.feed(text)|TypeError: a bytes-like object is required, not 'NoneType'|
'Gene Amplification in Human Cancers: Biological and Clinical Significance.';Traceback (most recent call last):|  File "/home/dmitry/PycharmProjects/VeriFast/./app/Background_tasks.py", line 34, in download_article|    xml_file_text, source = await SearcherObj(doi_or_name)|  File "/home/dmitry/PycharmProjects/VeriFast/./searcher.py", line 61, in __call__|    id_tuple = self.convert_id(crossref_meta["DOI"])|  File "/home/dmitry/PycharmProjects/VeriFast/./searcher.py", line 109, in convert_id|    print(record.pmid, record.pmcid, record.doi)|AttributeError: 'NoneType' object has no attribute 'pmid'|
'Gene amplification in cancer.';Traceback (most recent call last):|  File "/home/dmitry/PycharmProjects/VeriFast/./app/Background_tasks.py", line 34, in download_article|    xml_file_text, source = await SearcherObj(doi_or_name)|  File "/home/dmitry/PycharmProjects/VeriFast/./searcher.py", line 61, in __call__|    id_tuple = self.convert_id(crossref_meta["DOI"])|  File "/home/dmitry/PycharmProjects/VeriFast/./searcher.py", line 109, in convert_id|    print(record.pmid, record.pmcid, record.doi)|AttributeError: 'NoneType' object has no attribute 'pmid'|
'Patterns of genomic imbalances in human solid tumors.';Traceback (most recent call last):|  File "/home/dmitry/PycharmProjects/VeriFast/./app/Background_tasks.py", line 34, in download_article|    xml_file_text, source = await SearcherObj(doi_or_name)|  File "/home/dmitry/PycharmProjects/VeriFast/./searcher.py", line 68, in __call__|    pmc_parsed = ET.fromstring(pmc_xml)|  File "/home/dmitry/.conda/envs/VeriFast/lib/python3.9/xml/etree/ElementTree.py", line 1347, in XML|    parser.feed(text)|TypeError: a bytes-like object is required, not 'NoneType'|
'Chromosomal imbalances in human lung cancer.';Traceback (most recent call last):|  File "/home/dmitry/PycharmProjects/VeriFast/./app/Background_tasks.py", line 34, in download_article|    xml_file_text, source = await SearcherObj(doi_or_name)|  File "/home/dmitry/PycharmProjects/VeriFast/./searcher.py", line 68, in __call__|    pmc_parsed = ET.fromstring(pmc_xml)|  File "/home/dmitry/.conda/envs/VeriFast/lib/python3.9/xml/etree/ElementTree.py", line 1347, in XML|    parser.feed(text)|TypeError: a bytes-like object is required, not 'NoneType'|
'Genomic copy number analysis of non-small cell lung cancer using array comparative genomic hybridization: implications of the phosphatidylinositol 3-kinase pathway.';Traceback (most recent call last):|  File "/home/dmitry/PycharmProjects/VeriFast/./app/Background_tasks.py", line 34, in download_article|    xml_file_text, source = await SearcherObj(doi_or_name)|  File "/home/dmitry/PycharmProjects/VeriFast/./searcher.py", line 61, in __call__|    id_tuple = self.convert_id(crossref_meta["DOI"])|  File "/home/dmitry/PycharmProjects/VeriFast/./searcher.py", line 109, in convert_id|    print(record.pmid, record.pmcid, record.doi)|AttributeError: 'NoneType' object has no attribute 'pmid'|
'Squamous cell carcinoma related oncogene/DCUN1D1 is highly conserved and activated by amplification in squamous cell carcinomas.';Traceback (most recent call last):|  File "/home/dmitry/PycharmProjects/VeriFast/./app/Background_tasks.py", line 34, in download_article|    xml_file_text, source = await SearcherObj(doi_or_name)|  File "/home/dmitry/PycharmProjects/VeriFast/./searcher.py", line 68, in __call__|    pmc_parsed = ET.fromstring(pmc_xml)|  File "/home/dmitry/.conda/envs/VeriFast/lib/python3.9/xml/etree/ElementTree.py", line 1347, in XML|    parser.feed(text)|TypeError: a bytes-like object is required, not 'NoneType'|
'Genomic changes defining the genesis, progression, and malignancy potential in solid human tumours: a phenotype/genotype correlation.';Traceback (most recent call last):|  File "/home/dmitry/PycharmProjects/VeriFast/./app/Background_tasks.py", line 34, in download_article|    xml_file_text, source = await SearcherObj(doi_or_name)|  File "/home/dmitry/PycharmProjects/VeriFast/./searcher.py", line 68, in __call__|    pmc_parsed = ET.fromstring(pmc_xml)|  File "/home/dmitry/.conda/envs/VeriFast/lib/python3.9/xml/etree/ElementTree.py", line 1347, in XML|    parser.feed(text)|TypeError: a bytes-like object is required, not 'NoneType'|
'Dissecting self-renewal in stem cells with RNA interference.';Traceback (most recent call last):|  File "/home/dmitry/PycharmProjects/VeriFast/./app/Background_tasks.py", line 34, in download_article|    xml_file_text, source = await SearcherObj(doi_or_name)|  File "/home/dmitry/PycharmProjects/VeriFast/./searcher.py", line 68, in __call__|    pmc_parsed = ET.fromstring(pmc_xml)|  File "/home/dmitry/.conda/envs/VeriFast/lib/python3.9/xml/etree/ElementTree.py", line 1347, in XML|    parser.feed(text)|TypeError: a bytes-like object is required, not 'NoneType'|
'Chromosomal signatures of a subset of high-grade premalignant cervical lesions closely resemble invasive carcinomas.';Traceback (most recent call last):|  File "/home/dmitry/PycharmProjects/VeriFast/./app/Background_tasks.py", line 34, in download_article|    xml_file_text, source = await SearcherObj(doi_or_name)|  File "/home/dmitry/PycharmProjects/VeriFast/./searcher.py", line 68, in __call__|    pmc_parsed = ET.fromstring(pmc_xml)|  File "/home/dmitry/.conda/envs/VeriFast/lib/python3.9/xml/etree/ElementTree.py", line 1347, in XML|    parser.feed(text)|TypeError: a bytes-like object is required, not 'NoneType'|
'In vitro reprogramming of fibroblasts into a pluripotent ES-cell-like state.';Traceback (most recent call last):|  File "/home/dmitry/PycharmProjects/VeriFast/./app/Background_tasks.py", line 34, in download_article|    xml_file_text, source = await SearcherObj(doi_or_name)|  File "/home/dmitry/PycharmProjects/VeriFast/./searcher.py", line 61, in __call__|    id_tuple = self.convert_id(crossref_meta["DOI"])|  File "/home/dmitry/PycharmProjects/VeriFast/./searcher.py", line 109, in convert_id|    print(record.pmid, record.pmcid, record.doi)|AttributeError: 'NoneType' object has no attribute 'pmid'|
'Classification of human lung carcinomas by mRNA expression profiling reveals distinct adenocarcinoma subclasses.';Traceback (most recent call last):|  File "/home/dmitry/PycharmProjects/VeriFast/./app/Background_tasks.py", line 34, in download_article|    xml_file_text, source = await SearcherObj(doi_or_name)|  File "/home/dmitry/PycharmProjects/VeriFast/./searcher.py", line 61, in __call__|    id_tuple = self.convert_id(crossref_meta["DOI"])|  File "/home/dmitry/PycharmProjects/VeriFast/./searcher.py", line 109, in convert_id|    print(record.pmid, record.pmcid, record.doi)|AttributeError: 'NoneType' object has no attribute 'pmid'|
'PGC-1alpha-responsive genes involved in oxidative phosphorylation are coordinately downregulated in human diabetes.';Traceback (most recent call last):|  File "/home/dmitry/PycharmProjects/VeriFast/./app/Background_tasks.py", line 34, in download_article|    xml_file_text, source = await SearcherObj(doi_or_name)|  File "/home/dmitry/PycharmProjects/VeriFast/./searcher.py", line 61, in __call__|    id_tuple = self.convert_id(crossref_meta["DOI"])|  File "/home/dmitry/PycharmProjects/VeriFast/./searcher.py", line 109, in convert_id|    print(record.pmid, record.pmcid, record.doi)|AttributeError: 'NoneType' object has no attribute 'pmid'|
'A module map showing conditional activity of expression modules in cancer.';Traceback (most recent call last):|  File "/home/dmitry/PycharmProjects/VeriFast/./app/Background_tasks.py", line 34, in download_article|    xml_file_text, source = await SearcherObj(doi_or_name)|  File "/home/dmitry/PycharmProjects/VeriFast/./searcher.py", line 68, in __call__|    pmc_parsed = ET.fromstring(pmc_xml)|  File "/home/dmitry/.conda/envs/VeriFast/lib/python3.9/xml/etree/ElementTree.py", line 1347, in XML|    parser.feed(text)|TypeError: a bytes-like object is required, not 'NoneType'|
'Diversity of gene expression in adenocarcinoma of the lung.';Traceback (most recent call last):|  File "/home/dmitry/PycharmProjects/VeriFast/./app/Background_tasks.py", line 34, in download_article|    xml_file_text, source = await SearcherObj(doi_or_name)|  File "/home/dmitry/PycharmProjects/VeriFast/./searcher.py", line 61, in __call__|    id_tuple = self.convert_id(crossref_meta["DOI"])|  File "/home/dmitry/PycharmProjects/VeriFast/./searcher.py", line 109, in convert_id|    print(record.pmid, record.pmcid, record.doi)|AttributeError: 'NoneType' object has no attribute 'pmid'|
'Gene set enrichment analysis: a knowledge-based approach for interpreting genome-wide expression profiles.';Traceback (most recent call last):|  File "/home/dmitry/.conda/envs/VeriFast/lib/python3.9/site-packages/redis/connection.py", line 1198, in get_connection|    if connection.can_read():|  File "/home/dmitry/.conda/envs/VeriFast/lib/python3.9/site-packages/redis/connection.py", line 734, in can_read|    return self._parser.can_read(timeout)|  File "/home/dmitry/.conda/envs/VeriFast/lib/python3.9/site-packages/redis/connection.py", line 321, in can_read|    return self._buffer and self._buffer.can_read(timeout)|  File "/home/dmitry/.conda/envs/VeriFast/lib/python3.9/site-packages/redis/connection.py", line 230, in can_read|    self._read_from_socket(timeout=timeout,|  File "/home/dmitry/.conda/envs/VeriFast/lib/python3.9/site-packages/redis/connection.py", line 201, in _read_from_socket|    raise ConnectionError(SERVER_CLOSED_CONNECTION_ERROR)|redis.exceptions.ConnectionError: Connection closed by server.||During handling of the above exception, another exception occurred:||Traceback (most recent call last):|  File "/home/dmitry/.conda/envs/VeriFast/lib/python3.9/site-packages/redis/connection.py", line 559, in connect|    sock = self._connect()|  File "/home/dmitry/.conda/envs/VeriFast/lib/python3.9/site-packages/redis/connection.py", line 615, in _connect|    raise err|  File "/home/dmitry/.conda/envs/VeriFast/lib/python3.9/site-packages/redis/connection.py", line 603, in _connect|    sock.connect(socket_address)|ConnectionRefusedError: [Errno 111] Connection refused||During handling of the above exception, another exception occurred:||Traceback (most recent call last):|  File "/home/dmitry/PycharmProjects/VeriFast/./app/Background_tasks.py", line 59, in download_article|    job.save_meta()|  File "/home/dmitry/.conda/envs/VeriFast/lib/python3.9/site-packages/rq/job.py", line 679, in save_meta|    self.connection.hset(self.key, 'meta', meta)|  File "/home/dmitry/.conda/envs/VeriFast/lib/python3.9/site-packages/redis/client.py", line 3050, in hset|    return self.execute_command('HSET', name, *items)|  File "/home/dmitry/.conda/envs/VeriFast/lib/python3.9/site-packages/redis/client.py", line 898, in execute_command|    conn = self.connection or pool.get_connection(command_name, **options)|  File "/home/dmitry/.conda/envs/VeriFast/lib/python3.9/site-packages/redis/connection.py", line 1202, in get_connection|    connection.connect()|  File "/home/dmitry/.conda/envs/VeriFast/lib/python3.9/site-packages/redis/connection.py", line 563, in connect|    raise ConnectionError(self._error_message(e))|redis.exceptions.ConnectionError: Error 111 connecting to localhost:6379. Connection refused.|
'Module map of stem cell genes guides creation of epithelial cancer stem cells.';Traceback (most recent call last):|  File "/home/dmitry/.conda/envs/VeriFast/lib/python3.9/site-packages/redis/connection.py", line 1198, in get_connection|    if connection.can_read():|  File "/home/dmitry/.conda/envs/VeriFast/lib/python3.9/site-packages/redis/connection.py", line 734, in can_read|    return self._parser.can_read(timeout)|  File "/home/dmitry/.conda/envs/VeriFast/lib/python3.9/site-packages/redis/connection.py", line 321, in can_read|    return self._buffer and self._buffer.can_read(timeout)|  File "/home/dmitry/.conda/envs/VeriFast/lib/python3.9/site-packages/redis/connection.py", line 230, in can_read|    self._read_from_socket(timeout=timeout,|  File "/home/dmitry/.conda/envs/VeriFast/lib/python3.9/site-packages/redis/connection.py", line 201, in _read_from_socket|    raise ConnectionError(SERVER_CLOSED_CONNECTION_ERROR)|redis.exceptions.ConnectionError: Connection closed by server.||During handling of the above exception, another exception occurred:||Traceback (most recent call last):|  File "/home/dmitry/.conda/envs/VeriFast/lib/python3.9/site-packages/redis/connection.py", line 559, in connect|    sock = self._connect()|  File "/home/dmitry/.conda/envs/VeriFast/lib/python3.9/site-packages/redis/connection.py", line 615, in _connect|    raise err|  File "/home/dmitry/.conda/envs/VeriFast/lib/python3.9/site-packages/redis/connection.py", line 603, in _connect|    sock.connect(socket_address)|ConnectionRefusedError: [Errno 111] Connection refused||During handling of the above exception, another exception occurred:||Traceback (most recent call last):|  File "/home/dmitry/PycharmProjects/VeriFast/./app/Background_tasks.py", line 59, in download_article|    job.save_meta()|  File "/home/dmitry/.conda/envs/VeriFast/lib/python3.9/site-packages/rq/job.py", line 679, in save_meta|    self.connection.hset(self.key, 'meta', meta)|  File "/home/dmitry/.conda/envs/VeriFast/lib/python3.9/site-packages/redis/client.py", line 3050, in hset|    return self.execute_command('HSET', name, *items)|  File "/home/dmitry/.conda/envs/VeriFast/lib/python3.9/site-packages/redis/client.py", line 898, in execute_command|    conn = self.connection or pool.get_connection(command_name, **options)|  File "/home/dmitry/.conda/envs/VeriFast/lib/python3.9/site-packages/redis/connection.py", line 1202, in get_connection|    connection.connect()|  File "/home/dmitry/.conda/envs/VeriFast/lib/python3.9/site-packages/redis/connection.py", line 563, in connect|    raise ConnectionError(self._error_message(e))|redis.exceptions.ConnectionError: Error 111 connecting to localhost:6379. Connection refused.|
'';Traceback (most recent call last):|  File "/home/dmitry/PycharmProjects/VeriFast/./app/Background_tasks.py", line 34, in download_article|    xml_file_text, source = await SearcherObj(doi_or_name)|  File "/home/dmitry/PycharmProjects/VeriFast/./searcher.py", line 49, in __call__|    raise Exception("No valid input to searcher is provided")|Exception: No valid input to searcher is provided|
'Large-scale meta-analysis of cancer microarray data identifies common transcriptional profiles of neoplastic transformation and progression.';Traceback (most recent call last):|  File "/home/dmitry/.conda/envs/VeriFast/lib/python3.9/site-packages/redis/connection.py", line 1198, in get_connection|    if connection.can_read():|  File "/home/dmitry/.conda/envs/VeriFast/lib/python3.9/site-packages/redis/connection.py", line 734, in can_read|    return self._parser.can_read(timeout)|  File "/home/dmitry/.conda/envs/VeriFast/lib/python3.9/site-packages/redis/connection.py", line 321, in can_read|    return self._buffer and self._buffer.can_read(timeout)|  File "/home/dmitry/.conda/envs/VeriFast/lib/python3.9/site-packages/redis/connection.py", line 230, in can_read|    self._read_from_socket(timeout=timeout,|  File "/home/dmitry/.conda/envs/VeriFast/lib/python3.9/site-packages/redis/connection.py", line 201, in _read_from_socket|    raise ConnectionError(SERVER_CLOSED_CONNECTION_ERROR)|redis.exceptions.ConnectionError: Connection closed by server.||During handling of the above exception, another exception occurred:||Traceback (most recent call last):|  File "/home/dmitry/.conda/envs/VeriFast/lib/python3.9/site-packages/redis/connection.py", line 559, in connect|    sock = self._connect()|  File "/home/dmitry/.conda/envs/VeriFast/lib/python3.9/site-packages/redis/connection.py", line 615, in _connect|    raise err|  File "/home/dmitry/.conda/envs/VeriFast/lib/python3.9/site-packages/redis/connection.py", line 603, in _connect|    sock.connect(socket_address)|ConnectionRefusedError: [Errno 111] Connection refused||During handling of the above exception, another exception occurred:||Traceback (most recent call last):|  File "/home/dmitry/PycharmProjects/VeriFast/./app/Background_tasks.py", line 59, in download_article|    job.save_meta()|  File "/home/dmitry/.conda/envs/VeriFast/lib/python3.9/site-packages/rq/job.py", line 679, in save_meta|    self.connection.hset(self.key, 'meta', meta)|  File "/home/dmitry/.conda/envs/VeriFast/lib/python3.9/site-packages/redis/client.py", line 3050, in hset|    return self.execute_command('HSET', name, *items)|  File "/home/dmitry/.conda/envs/VeriFast/lib/python3.9/site-packages/redis/client.py", line 898, in execute_command|    conn = self.connection or pool.get_connection(command_name, **options)|  File "/home/dmitry/.conda/envs/VeriFast/lib/python3.9/site-packages/redis/connection.py", line 1202, in get_connection|    connection.connect()|  File "/home/dmitry/.conda/envs/VeriFast/lib/python3.9/site-packages/redis/connection.py", line 563, in connect|    raise ConnectionError(self._error_message(e))|redis.exceptions.ConnectionError: Error 111 connecting to localhost:6379. Connection refused.|
'Lung carcinomas with a basaloid pattern: a study of 90 cases focusing on their poor prognosis.';Traceback (most recent call last):|  File "/home/dmitry/PycharmProjects/VeriFast/./app/Background_tasks.py", line 34, in download_article|    xml_file_text, source = await SearcherObj(doi_or_name)|  File "/home/dmitry/PycharmProjects/VeriFast/./searcher.py", line 68, in __call__|    pmc_parsed = ET.fromstring(pmc_xml)|  File "/home/dmitry/.conda/envs/VeriFast/lib/python3.9/xml/etree/ElementTree.py", line 1347, in XML|    parser.feed(text)|TypeError: a bytes-like object is required, not 'NoneType'|
'Altered regulation of c-jun and its involvement in anchorage-independent growth of human lung cancers.';Traceback (most recent call last):|  File "/home/dmitry/PycharmProjects/VeriFast/./app/Background_tasks.py", line 34, in download_article|    xml_file_text, source = await SearcherObj(doi_or_name)|  File "/home/dmitry/PycharmProjects/VeriFast/./searcher.py", line 68, in __call__|    pmc_parsed = ET.fromstring(pmc_xml)|  File "/home/dmitry/.conda/envs/VeriFast/lib/python3.9/xml/etree/ElementTree.py", line 1347, in XML|    parser.feed(text)|TypeError: a bytes-like object is required, not 'NoneType'|
'Oncogenic PI3K and its role in cancer.';Traceback (most recent call last):|  File "/home/dmitry/PycharmProjects/VeriFast/./app/Background_tasks.py", line 34, in download_article|    xml_file_text, source = await SearcherObj(doi_or_name)|  File "/home/dmitry/PycharmProjects/VeriFast/./searcher.py", line 68, in __call__|    pmc_parsed = ET.fromstring(pmc_xml)|  File "/home/dmitry/.conda/envs/VeriFast/lib/python3.9/xml/etree/ElementTree.py", line 1347, in XML|    parser.feed(text)|TypeError: a bytes-like object is required, not 'NoneType'|
'An embryonic stem cell-like gene expression signature in poorly differentiated aggressive human tumors.';Traceback (most recent call last):|  File "/home/dmitry/.conda/envs/VeriFast/lib/python3.9/site-packages/redis/connection.py", line 1198, in get_connection|    if connection.can_read():|  File "/home/dmitry/.conda/envs/VeriFast/lib/python3.9/site-packages/redis/connection.py", line 734, in can_read|    return self._parser.can_read(timeout)|  File "/home/dmitry/.conda/envs/VeriFast/lib/python3.9/site-packages/redis/connection.py", line 321, in can_read|    return self._buffer and self._buffer.can_read(timeout)|  File "/home/dmitry/.conda/envs/VeriFast/lib/python3.9/site-packages/redis/connection.py", line 230, in can_read|    self._read_from_socket(timeout=timeout,|  File "/home/dmitry/.conda/envs/VeriFast/lib/python3.9/site-packages/redis/connection.py", line 201, in _read_from_socket|    raise ConnectionError(SERVER_CLOSED_CONNECTION_ERROR)|redis.exceptions.ConnectionError: Connection closed by server.||During handling of the above exception, another exception occurred:||Traceback (most recent call last):|  File "/home/dmitry/.conda/envs/VeriFast/lib/python3.9/site-packages/redis/connection.py", line 559, in connect|    sock = self._connect()|  File "/home/dmitry/.conda/envs/VeriFast/lib/python3.9/site-packages/redis/connection.py", line 615, in _connect|    raise err|  File "/home/dmitry/.conda/envs/VeriFast/lib/python3.9/site-packages/redis/connection.py", line 603, in _connect|    sock.connect(socket_address)|ConnectionRefusedError: [Errno 111] Connection refused||During handling of the above exception, another exception occurred:||Traceback (most recent call last):|  File "/home/dmitry/PycharmProjects/VeriFast/./app/Background_tasks.py", line 59, in download_article|    job.save_meta()|  File "/home/dmitry/.conda/envs/VeriFast/lib/python3.9/site-packages/rq/job.py", line 679, in save_meta|    self.connection.hset(self.key, 'meta', meta)|  File "/home/dmitry/.conda/envs/VeriFast/lib/python3.9/site-packages/redis/client.py", line 3050, in hset|    return self.execute_command('HSET', name, *items)|  File "/home/dmitry/.conda/envs/VeriFast/lib/python3.9/site-packages/redis/client.py", line 898, in execute_command|    conn = self.connection or pool.get_connection(command_name, **options)|  File "/home/dmitry/.conda/envs/VeriFast/lib/python3.9/site-packages/redis/connection.py", line 1202, in get_connection|    connection.connect()|  File "/home/dmitry/.conda/envs/VeriFast/lib/python3.9/site-packages/redis/connection.py", line 563, in connect|    raise ConnectionError(self._error_message(e))|redis.exceptions.ConnectionError: Error 111 connecting to localhost:6379. Connection refused.|
'Human bronchial epithelial cells with integrated SV40 virus T antigen genes retain the ability to undergo squamous differentiation.';Traceback (most recent call last):|  File "/home/dmitry/.conda/envs/VeriFast/lib/python3.9/site-packages/redis/connection.py", line 1198, in get_connection|    if connection.can_read():|  File "/home/dmitry/.conda/envs/VeriFast/lib/python3.9/site-packages/redis/connection.py", line 734, in can_read|    return self._parser.can_read(timeout)|  File "/home/dmitry/.conda/envs/VeriFast/lib/python3.9/site-packages/redis/connection.py", line 321, in can_read|    return self._buffer and self._buffer.can_read(timeout)|  File "/home/dmitry/.conda/envs/VeriFast/lib/python3.9/site-packages/redis/connection.py", line 230, in can_read|    self._read_from_socket(timeout=timeout,|  File "/home/dmitry/.conda/envs/VeriFast/lib/python3.9/site-packages/redis/connection.py", line 201, in _read_from_socket|    raise ConnectionError(SERVER_CLOSED_CONNECTION_ERROR)|redis.exceptions.ConnectionError: Connection closed by server.||During handling of the above exception, another exception occurred:||Traceback (most recent call last):|  File "/home/dmitry/.conda/envs/VeriFast/lib/python3.9/site-packages/redis/connection.py", line 559, in connect|    sock = self._connect()|  File "/home/dmitry/.conda/envs/VeriFast/lib/python3.9/site-packages/redis/connection.py", line 615, in _connect|    raise err|  File "/home/dmitry/.conda/envs/VeriFast/lib/python3.9/site-packages/redis/connection.py", line 603, in _connect|    sock.connect(socket_address)|ConnectionRefusedError: [Errno 111] Connection refused||During handling of the above exception, another exception occurred:||Traceback (most recent call last):|  File "/home/dmitry/PycharmProjects/VeriFast/./app/Background_tasks.py", line 59, in download_article|    job.save_meta()|  File "/home/dmitry/.conda/envs/VeriFast/lib/python3.9/site-packages/rq/job.py", line 679, in save_meta|    self.connection.hset(self.key, 'meta', meta)|  File "/home/dmitry/.conda/envs/VeriFast/lib/python3.9/site-packages/redis/client.py", line 3050, in hset|    return self.execute_command('HSET', name, *items)|  File "/home/dmitry/.conda/envs/VeriFast/lib/python3.9/site-packages/redis/client.py", line 898, in execute_command|    conn = self.connection or pool.get_connection(command_name, **options)|  File "/home/dmitry/.conda/envs/VeriFast/lib/python3.9/site-packages/redis/connection.py", line 1202, in get_connection|    connection.connect()|  File "/home/dmitry/.conda/envs/VeriFast/lib/python3.9/site-packages/redis/connection.py", line 563, in connect|    raise ConnectionError(self._error_message(e))|redis.exceptions.ConnectionError: Error 111 connecting to localhost:6379. Connection refused.|
'Cellular tumorigenicity in nude mice: correlation with cell growth in semi-solid medium.';Traceback (most recent call last):|  File "/home/dmitry/.conda/envs/VeriFast/lib/python3.9/site-packages/redis/connection.py", line 1198, in get_connection|    if connection.can_read():|  File "/home/dmitry/.conda/envs/VeriFast/lib/python3.9/site-packages/redis/connection.py", line 734, in can_read|    return self._parser.can_read(timeout)|  File "/home/dmitry/.conda/envs/VeriFast/lib/python3.9/site-packages/redis/connection.py", line 321, in can_read|    return self._buffer and self._buffer.can_read(timeout)|  File "/home/dmitry/.conda/envs/VeriFast/lib/python3.9/site-packages/redis/connection.py", line 230, in can_read|    self._read_from_socket(timeout=timeout,|  File "/home/dmitry/.conda/envs/VeriFast/lib/python3.9/site-packages/redis/connection.py", line 201, in _read_from_socket|    raise ConnectionError(SERVER_CLOSED_CONNECTION_ERROR)|redis.exceptions.ConnectionError: Connection closed by server.||During handling of the above exception, another exception occurred:||Traceback (most recent call last):|  File "/home/dmitry/.conda/envs/VeriFast/lib/python3.9/site-packages/redis/connection.py", line 559, in connect|    sock = self._connect()|  File "/home/dmitry/.conda/envs/VeriFast/lib/python3.9/site-packages/redis/connection.py", line 615, in _connect|    raise err|  File "/home/dmitry/.conda/envs/VeriFast/lib/python3.9/site-packages/redis/connection.py", line 603, in _connect|    sock.connect(socket_address)|ConnectionRefusedError: [Errno 111] Connection refused||During handling of the above exception, another exception occurred:||Traceback (most recent call last):|  File "/home/dmitry/PycharmProjects/VeriFast/./app/Background_tasks.py", line 59, in download_article|    job.save_meta()|  File "/home/dmitry/.conda/envs/VeriFast/lib/python3.9/site-packages/rq/job.py", line 679, in save_meta|    self.connection.hset(self.key, 'meta', meta)|  File "/home/dmitry/.conda/envs/VeriFast/lib/python3.9/site-packages/redis/client.py", line 3050, in hset|    return self.execute_command('HSET', name, *items)|  File "/home/dmitry/.conda/envs/VeriFast/lib/python3.9/site-packages/redis/client.py", line 898, in execute_command|    conn = self.connection or pool.get_connection(command_name, **options)|  File "/home/dmitry/.conda/envs/VeriFast/lib/python3.9/site-packages/redis/connection.py", line 1202, in get_connection|    connection.connect()|  File "/home/dmitry/.conda/envs/VeriFast/lib/python3.9/site-packages/redis/connection.py", line 563, in connect|    raise ConnectionError(self._error_message(e))|redis.exceptions.ConnectionError: Error 111 connecting to localhost:6379. Connection refused.|
'SCCRO (DCUN1D1) induces extracellular matrix invasion by activating matrix metalloproteinase 2.';Traceback (most recent call last):|  File "/home/dmitry/PycharmProjects/VeriFast/./app/Background_tasks.py", line 34, in download_article|    xml_file_text, source = await SearcherObj(doi_or_name)|  File "/home/dmitry/PycharmProjects/VeriFast/./searcher.py", line 54, in __call__|    crossref_meta = self.crossref_search_meta(search_query)|  File "/home/dmitry/PycharmProjects/VeriFast/./searcher.py", line 128, in crossref_search_meta|    if re.match(item["title"][0], query, re.IGNORECASE):|KeyError: 'title'|
'Activation of the hedgehog pathway in a subset of lung cancers.';Traceback (most recent call last):|  File "/home/dmitry/.conda/envs/VeriFast/lib/python3.9/site-packages/redis/connection.py", line 1198, in get_connection|    if connection.can_read():|  File "/home/dmitry/.conda/envs/VeriFast/lib/python3.9/site-packages/redis/connection.py", line 734, in can_read|    return self._parser.can_read(timeout)|  File "/home/dmitry/.conda/envs/VeriFast/lib/python3.9/site-packages/redis/connection.py", line 321, in can_read|    return self._buffer and self._buffer.can_read(timeout)|  File "/home/dmitry/.conda/envs/VeriFast/lib/python3.9/site-packages/redis/connection.py", line 230, in can_read|    self._read_from_socket(timeout=timeout,|  File "/home/dmitry/.conda/envs/VeriFast/lib/python3.9/site-packages/redis/connection.py", line 201, in _read_from_socket|    raise ConnectionError(SERVER_CLOSED_CONNECTION_ERROR)|redis.exceptions.ConnectionError: Connection closed by server.||During handling of the above exception, another exception occurred:||Traceback (most recent call last):|  File "/home/dmitry/.conda/envs/VeriFast/lib/python3.9/site-packages/redis/connection.py", line 559, in connect|    sock = self._connect()|  File "/home/dmitry/.conda/envs/VeriFast/lib/python3.9/site-packages/redis/connection.py", line 615, in _connect|    raise err|  File "/home/dmitry/.conda/envs/VeriFast/lib/python3.9/site-packages/redis/connection.py", line 603, in _connect|    sock.connect(socket_address)|ConnectionRefusedError: [Errno 111] Connection refused||During handling of the above exception, another exception occurred:||Traceback (most recent call last):|  File "/home/dmitry/PycharmProjects/VeriFast/./app/Background_tasks.py", line 59, in download_article|    job.save_meta()|  File "/home/dmitry/.conda/envs/VeriFast/lib/python3.9/site-packages/rq/job.py", line 679, in save_meta|    self.connection.hset(self.key, 'meta', meta)|  File "/home/dmitry/.conda/envs/VeriFast/lib/python3.9/site-packages/redis/client.py", line 3050, in hset|    return self.execute_command('HSET', name, *items)|  File "/home/dmitry/.conda/envs/VeriFast/lib/python3.9/site-packages/redis/client.py", line 898, in execute_command|    conn = self.connection or pool.get_connection(command_name, **options)|  File "/home/dmitry/.conda/envs/VeriFast/lib/python3.9/site-packages/redis/connection.py", line 1202, in get_connection|    connection.connect()|  File "/home/dmitry/.conda/envs/VeriFast/lib/python3.9/site-packages/redis/connection.py", line 563, in connect|    raise ConnectionError(self._error_message(e))|redis.exceptions.ConnectionError: Error 111 connecting to localhost:6379. Connection refused.|
'The conserved protein DCN-1/Dcn1p is required for cullin neddylation in';Traceback (most recent call last):|  File "/home/dmitry/PycharmProjects/VeriFast/./app/Background_tasks.py", line 34, in download_article|    xml_file_text, source = await SearcherObj(doi_or_name)|  File "/home/dmitry/PycharmProjects/VeriFast/./searcher.py", line 61, in __call__|    id_tuple = self.convert_id(crossref_meta["DOI"])|  File "/home/dmitry/PycharmProjects/VeriFast/./searcher.py", line 109, in convert_id|    print(record.pmid, record.pmcid, record.doi)|AttributeError: 'NoneType' object has no attribute 'pmid'|
'A meta-analysis of human embryonic stem cells transcriptome integrated into a web-based expression atlas.';Traceback (most recent call last):|  File "/home/dmitry/.conda/envs/VeriFast/lib/python3.9/site-packages/redis/connection.py", line 1198, in get_connection|    if connection.can_read():|  File "/home/dmitry/.conda/envs/VeriFast/lib/python3.9/site-packages/redis/connection.py", line 734, in can_read|    return self._parser.can_read(timeout)|  File "/home/dmitry/.conda/envs/VeriFast/lib/python3.9/site-packages/redis/connection.py", line 321, in can_read|    return self._buffer and self._buffer.can_read(timeout)|  File "/home/dmitry/.conda/envs/VeriFast/lib/python3.9/site-packages/redis/connection.py", line 230, in can_read|    self._read_from_socket(timeout=timeout,|  File "/home/dmitry/.conda/envs/VeriFast/lib/python3.9/site-packages/redis/connection.py", line 201, in _read_from_socket|    raise ConnectionError(SERVER_CLOSED_CONNECTION_ERROR)|redis.exceptions.ConnectionError: Connection closed by server.||During handling of the above exception, another exception occurred:||Traceback (most recent call last):|  File "/home/dmitry/.conda/envs/VeriFast/lib/python3.9/site-packages/redis/connection.py", line 559, in connect|    sock = self._connect()|  File "/home/dmitry/.conda/envs/VeriFast/lib/python3.9/site-packages/redis/connection.py", line 615, in _connect|    raise err|  File "/home/dmitry/.conda/envs/VeriFast/lib/python3.9/site-packages/redis/connection.py", line 603, in _connect|    sock.connect(socket_address)|ConnectionRefusedError: [Errno 111] Connection refused||During handling of the above exception, another exception occurred:||Traceback (most recent call last):|  File "/home/dmitry/PycharmProjects/VeriFast/./app/Background_tasks.py", line 59, in download_article|    job.save_meta()|  File "/home/dmitry/.conda/envs/VeriFast/lib/python3.9/site-packages/rq/job.py", line 679, in save_meta|    self.connection.hset(self.key, 'meta', meta)|  File "/home/dmitry/.conda/envs/VeriFast/lib/python3.9/site-packages/redis/client.py", line 3050, in hset|    return self.execute_command('HSET', name, *items)|  File "/home/dmitry/.conda/envs/VeriFast/lib/python3.9/site-packages/redis/client.py", line 898, in execute_command|    conn = self.connection or pool.get_connection(command_name, **options)|  File "/home/dmitry/.conda/envs/VeriFast/lib/python3.9/site-packages/redis/connection.py", line 1202, in get_connection|    connection.connect()|  File "/home/dmitry/.conda/envs/VeriFast/lib/python3.9/site-packages/redis/connection.py", line 563, in connect|    raise ConnectionError(self._error_message(e))|redis.exceptions.ConnectionError: Error 111 connecting to localhost:6379. Connection refused.|
'Region-specific expression of chicken Sox2 in the developing gut and lung epithelium: regulation by epithelial-mesenchymal interactions.';Traceback (most recent call last):|  File "/home/dmitry/PycharmProjects/VeriFast/./app/Background_tasks.py", line 34, in download_article|    xml_file_text, source = await SearcherObj(doi_or_name)|  File "/home/dmitry/PycharmProjects/VeriFast/./searcher.py", line 68, in __call__|    pmc_parsed = ET.fromstring(pmc_xml)|  File "/home/dmitry/.conda/envs/VeriFast/lib/python3.9/xml/etree/ElementTree.py", line 1347, in XML|    parser.feed(text)|TypeError: a bytes-like object is required, not 'NoneType'|
'2004 World Health Organization classification of lung tumors.';Traceback (most recent call last):|  File "/home/dmitry/.conda/envs/VeriFast/lib/python3.9/site-packages/redis/connection.py", line 1198, in get_connection|    if connection.can_read():|  File "/home/dmitry/.conda/envs/VeriFast/lib/python3.9/site-packages/redis/connection.py", line 734, in can_read|    return self._parser.can_read(timeout)|  File "/home/dmitry/.conda/envs/VeriFast/lib/python3.9/site-packages/redis/connection.py", line 321, in can_read|    return self._buffer and self._buffer.can_read(timeout)|  File "/home/dmitry/.conda/envs/VeriFast/lib/python3.9/site-packages/redis/connection.py", line 230, in can_read|    self._read_from_socket(timeout=timeout,|  File "/home/dmitry/.conda/envs/VeriFast/lib/python3.9/site-packages/redis/connection.py", line 201, in _read_from_socket|    raise ConnectionError(SERVER_CLOSED_CONNECTION_ERROR)|redis.exceptions.ConnectionError: Connection closed by server.||During handling of the above exception, another exception occurred:||Traceback (most recent call last):|  File "/home/dmitry/.conda/envs/VeriFast/lib/python3.9/site-packages/redis/connection.py", line 559, in connect|    sock = self._connect()|  File "/home/dmitry/.conda/envs/VeriFast/lib/python3.9/site-packages/redis/connection.py", line 615, in _connect|    raise err|  File "/home/dmitry/.conda/envs/VeriFast/lib/python3.9/site-packages/redis/connection.py", line 603, in _connect|    sock.connect(socket_address)|ConnectionRefusedError: [Errno 111] Connection refused||During handling of the above exception, another exception occurred:||Traceback (most recent call last):|  File "/home/dmitry/PycharmProjects/VeriFast/./app/Background_tasks.py", line 59, in download_article|    job.save_meta()|  File "/home/dmitry/.conda/envs/VeriFast/lib/python3.9/site-packages/rq/job.py", line 679, in save_meta|    self.connection.hset(self.key, 'meta', meta)|  File "/home/dmitry/.conda/envs/VeriFast/lib/python3.9/site-packages/redis/client.py", line 3050, in hset|    return self.execute_command('HSET', name, *items)|  File "/home/dmitry/.conda/envs/VeriFast/lib/python3.9/site-packages/redis/client.py", line 898, in execute_command|    conn = self.connection or pool.get_connection(command_name, **options)|  File "/home/dmitry/.conda/envs/VeriFast/lib/python3.9/site-packages/redis/connection.py", line 1202, in get_connection|    connection.connect()|  File "/home/dmitry/.conda/envs/VeriFast/lib/python3.9/site-packages/redis/connection.py", line 563, in connect|    raise ConnectionError(self._error_message(e))|redis.exceptions.ConnectionError: Error 111 connecting to localhost:6379. Connection refused.|
'Histopathologic evaluation of stepwise progression of pancreatic carcinoma with immunohistochemical analysis of gastric epithelial transcription factor SOX2: comparison of expression patterns between invasive components and cancerous or nonneoplastic intraductal components.';Traceback (most recent call last):|  File "/home/dmitry/PycharmProjects/VeriFast/./app/Background_tasks.py", line 34, in download_article|    xml_file_text, source = await SearcherObj(doi_or_name)|  File "/home/dmitry/PycharmProjects/VeriFast/./searcher.py", line 68, in __call__|    pmc_parsed = ET.fromstring(pmc_xml)|  File "/home/dmitry/.conda/envs/VeriFast/lib/python3.9/xml/etree/ElementTree.py", line 1347, in XML|    parser.feed(text)|TypeError: a bytes-like object is required, not 'NoneType'|
'Deletion of XPC leads to lung tumors in mice and is associated with early events in human lung carcinogenesis.';Traceback (most recent call last):|  File "/home/dmitry/.conda/envs/VeriFast/lib/python3.9/site-packages/redis/connection.py", line 1198, in get_connection|    if connection.can_read():|  File "/home/dmitry/.conda/envs/VeriFast/lib/python3.9/site-packages/redis/connection.py", line 734, in can_read|    return self._parser.can_read(timeout)|  File "/home/dmitry/.conda/envs/VeriFast/lib/python3.9/site-packages/redis/connection.py", line 321, in can_read|    return self._buffer and self._buffer.can_read(timeout)|  File "/home/dmitry/.conda/envs/VeriFast/lib/python3.9/site-packages/redis/connection.py", line 230, in can_read|    self._read_from_socket(timeout=timeout,|  File "/home/dmitry/.conda/envs/VeriFast/lib/python3.9/site-packages/redis/connection.py", line 201, in _read_from_socket|    raise ConnectionError(SERVER_CLOSED_CONNECTION_ERROR)|redis.exceptions.ConnectionError: Connection closed by server.||During handling of the above exception, another exception occurred:||Traceback (most recent call last):|  File "/home/dmitry/.conda/envs/VeriFast/lib/python3.9/site-packages/redis/connection.py", line 559, in connect|    sock = self._connect()|  File "/home/dmitry/.conda/envs/VeriFast/lib/python3.9/site-packages/redis/connection.py", line 615, in _connect|    raise err|  File "/home/dmitry/.conda/envs/VeriFast/lib/python3.9/site-packages/redis/connection.py", line 603, in _connect|    sock.connect(socket_address)|ConnectionRefusedError: [Errno 111] Connection refused||During handling of the above exception, another exception occurred:||Traceback (most recent call last):|  File "/home/dmitry/PycharmProjects/VeriFast/./app/Background_tasks.py", line 59, in download_article|    job.save_meta()|  File "/home/dmitry/.conda/envs/VeriFast/lib/python3.9/site-packages/rq/job.py", line 679, in save_meta|    self.connection.hset(self.key, 'meta', meta)|  File "/home/dmitry/.conda/envs/VeriFast/lib/python3.9/site-packages/redis/client.py", line 3050, in hset|    return self.execute_command('HSET', name, *items)|  File "/home/dmitry/.conda/envs/VeriFast/lib/python3.9/site-packages/redis/client.py", line 898, in execute_command|    conn = self.connection or pool.get_connection(command_name, **options)|  File "/home/dmitry/.conda/envs/VeriFast/lib/python3.9/site-packages/redis/connection.py", line 1202, in get_connection|    connection.connect()|  File "/home/dmitry/.conda/envs/VeriFast/lib/python3.9/site-packages/redis/connection.py", line 563, in connect|    raise ConnectionError(self._error_message(e))|redis.exceptions.ConnectionError: Error 111 connecting to localhost:6379. Connection refused.|
'Gene expression profiles in pancreatic intraepithelial neoplasia reflect the effects of Hedgehog signaling on pancreatic ductal epithelial cells.';Traceback (most recent call last):|  File "/home/dmitry/PycharmProjects/VeriFast/./app/Background_tasks.py", line 34, in download_article|    xml_file_text, source = await SearcherObj(doi_or_name)|  File "/home/dmitry/PycharmProjects/VeriFast/./searcher.py", line 68, in __call__|    pmc_parsed = ET.fromstring(pmc_xml)|  File "/home/dmitry/.conda/envs/VeriFast/lib/python3.9/xml/etree/ElementTree.py", line 1347, in XML|    parser.feed(text)|TypeError: a bytes-like object is required, not 'NoneType'|
'';Traceback (most recent call last):|  File "/home/dmitry/PycharmProjects/VeriFast/./app/Background_tasks.py", line 34, in download_article|    xml_file_text, source = await SearcherObj(doi_or_name)|  File "/home/dmitry/PycharmProjects/VeriFast/./searcher.py", line 49, in __call__|    raise Exception("No valid input to searcher is provided")|Exception: No valid input to searcher is provided|
'Normal lung development and function after Sox9 inactivation in the respiratory epithelium.';Traceback (most recent call last):|  File "/home/dmitry/PycharmProjects/VeriFast/./app/Background_tasks.py", line 34, in download_article|    xml_file_text, source = await SearcherObj(doi_or_name)|  File "/home/dmitry/PycharmProjects/VeriFast/./searcher.py", line 68, in __call__|    pmc_parsed = ET.fromstring(pmc_xml)|  File "/home/dmitry/.conda/envs/VeriFast/lib/python3.9/xml/etree/ElementTree.py", line 1347, in XML|    parser.feed(text)|TypeError: a bytes-like object is required, not 'NoneType'|
'Non-coding RNAs: new players in eukaryotic biology.';Traceback (most recent call last):|  File "/home/dmitry/.conda/envs/VeriFast/lib/python3.9/site-packages/redis/connection.py", line 1198, in get_connection|    if connection.can_read():|  File "/home/dmitry/.conda/envs/VeriFast/lib/python3.9/site-packages/redis/connection.py", line 734, in can_read|    return self._parser.can_read(timeout)|  File "/home/dmitry/.conda/envs/VeriFast/lib/python3.9/site-packages/redis/connection.py", line 321, in can_read|    return self._buffer and self._buffer.can_read(timeout)|  File "/home/dmitry/.conda/envs/VeriFast/lib/python3.9/site-packages/redis/connection.py", line 230, in can_read|    self._read_from_socket(timeout=timeout,|  File "/home/dmitry/.conda/envs/VeriFast/lib/python3.9/site-packages/redis/connection.py", line 201, in _read_from_socket|    raise ConnectionError(SERVER_CLOSED_CONNECTION_ERROR)|redis.exceptions.ConnectionError: Connection closed by server.||During handling of the above exception, another exception occurred:||Traceback (most recent call last):|  File "/home/dmitry/.conda/envs/VeriFast/lib/python3.9/site-packages/redis/connection.py", line 559, in connect|    sock = self._connect()|  File "/home/dmitry/.conda/envs/VeriFast/lib/python3.9/site-packages/redis/connection.py", line 615, in _connect|    raise err|  File "/home/dmitry/.conda/envs/VeriFast/lib/python3.9/site-packages/redis/connection.py", line 603, in _connect|    sock.connect(socket_address)|ConnectionRefusedError: [Errno 111] Connection refused||During handling of the above exception, another exception occurred:||Traceback (most recent call last):|  File "/home/dmitry/PycharmProjects/VeriFast/./app/Background_tasks.py", line 59, in download_article|    job.save_meta()|  File "/home/dmitry/.conda/envs/VeriFast/lib/python3.9/site-packages/rq/job.py", line 679, in save_meta|    self.connection.hset(self.key, 'meta', meta)|  File "/home/dmitry/.conda/envs/VeriFast/lib/python3.9/site-packages/redis/client.py", line 3050, in hset|    return self.execute_command('HSET', name, *items)|  File "/home/dmitry/.conda/envs/VeriFast/lib/python3.9/site-packages/redis/client.py", line 898, in execute_command|    conn = self.connection or pool.get_connection(command_name, **options)|  File "/home/dmitry/.conda/envs/VeriFast/lib/python3.9/site-packages/redis/connection.py", line 1202, in get_connection|    connection.connect()|  File "/home/dmitry/.conda/envs/VeriFast/lib/python3.9/site-packages/redis/connection.py", line 563, in connect|    raise ConnectionError(self._error_message(e))|redis.exceptions.ConnectionError: Error 111 connecting to localhost:6379. Connection refused.|
'Identification of SOX2 as a novel glioma-associated antigen and potential target for T cell-based immunotherapy.';Traceback (most recent call last):|  File "/home/dmitry/.conda/envs/VeriFast/lib/python3.9/site-packages/redis/connection.py", line 1198, in get_connection|    if connection.can_read():|  File "/home/dmitry/.conda/envs/VeriFast/lib/python3.9/site-packages/redis/connection.py", line 734, in can_read|    return self._parser.can_read(timeout)|  File "/home/dmitry/.conda/envs/VeriFast/lib/python3.9/site-packages/redis/connection.py", line 321, in can_read|    return self._buffer and self._buffer.can_read(timeout)|  File "/home/dmitry/.conda/envs/VeriFast/lib/python3.9/site-packages/redis/connection.py", line 230, in can_read|    self._read_from_socket(timeout=timeout,|  File "/home/dmitry/.conda/envs/VeriFast/lib/python3.9/site-packages/redis/connection.py", line 201, in _read_from_socket|    raise ConnectionError(SERVER_CLOSED_CONNECTION_ERROR)|redis.exceptions.ConnectionError: Connection closed by server.||During handling of the above exception, another exception occurred:||Traceback (most recent call last):|  File "/home/dmitry/.conda/envs/VeriFast/lib/python3.9/site-packages/redis/connection.py", line 559, in connect|    sock = self._connect()|  File "/home/dmitry/.conda/envs/VeriFast/lib/python3.9/site-packages/redis/connection.py", line 615, in _connect|    raise err|  File "/home/dmitry/.conda/envs/VeriFast/lib/python3.9/site-packages/redis/connection.py", line 603, in _connect|    sock.connect(socket_address)|ConnectionRefusedError: [Errno 111] Connection refused||During handling of the above exception, another exception occurred:||Traceback (most recent call last):|  File "/home/dmitry/PycharmProjects/VeriFast/./app/Background_tasks.py", line 59, in download_article|    job.save_meta()|  File "/home/dmitry/.conda/envs/VeriFast/lib/python3.9/site-packages/rq/job.py", line 679, in save_meta|    self.connection.hset(self.key, 'meta', meta)|  File "/home/dmitry/.conda/envs/VeriFast/lib/python3.9/site-packages/redis/client.py", line 3050, in hset|    return self.execute_command('HSET', name, *items)|  File "/home/dmitry/.conda/envs/VeriFast/lib/python3.9/site-packages/redis/client.py", line 898, in execute_command|    conn = self.connection or pool.get_connection(command_name, **options)|  File "/home/dmitry/.conda/envs/VeriFast/lib/python3.9/site-packages/redis/connection.py", line 1202, in get_connection|    connection.connect()|  File "/home/dmitry/.conda/envs/VeriFast/lib/python3.9/site-packages/redis/connection.py", line 563, in connect|    raise ConnectionError(self._error_message(e))|redis.exceptions.ConnectionError: Error 111 connecting to localhost:6379. Connection refused.|
'Sox2: a possible driver of the basal-like phenotype in sporadic breast cancer.';Traceback (most recent call last):|  File "/home/dmitry/PycharmProjects/VeriFast/./app/Background_tasks.py", line 34, in download_article|    xml_file_text, source = await SearcherObj(doi_or_name)|  File "/home/dmitry/PycharmProjects/VeriFast/./searcher.py", line 68, in __call__|    pmc_parsed = ET.fromstring(pmc_xml)|  File "/home/dmitry/.conda/envs/VeriFast/lib/python3.9/xml/etree/ElementTree.py", line 1347, in XML|    parser.feed(text)|TypeError: a bytes-like object is required, not 'NoneType'|
'SOX2 silencing in glioblastoma tumor-initiating cells causes stop of proliferation and loss of tumorigenicity.';Traceback (most recent call last):|  File "/home/dmitry/PycharmProjects/VeriFast/./app/Background_tasks.py", line 34, in download_article|    xml_file_text, source = await SearcherObj(doi_or_name)|  File "/home/dmitry/PycharmProjects/VeriFast/./searcher.py", line 68, in __call__|    pmc_parsed = ET.fromstring(pmc_xml)|  File "/home/dmitry/.conda/envs/VeriFast/lib/python3.9/xml/etree/ElementTree.py", line 1347, in XML|    parser.feed(text)|TypeError: a bytes-like object is required, not 'NoneType'|
'Transdifferentiation of ciliated cells during repair of the respiratory epithelium.';Traceback (most recent call last):|  File "/home/dmitry/.conda/envs/VeriFast/lib/python3.9/site-packages/redis/connection.py", line 1198, in get_connection|    if connection.can_read():|  File "/home/dmitry/.conda/envs/VeriFast/lib/python3.9/site-packages/redis/connection.py", line 734, in can_read|    return self._parser.can_read(timeout)|  File "/home/dmitry/.conda/envs/VeriFast/lib/python3.9/site-packages/redis/connection.py", line 321, in can_read|    return self._buffer and self._buffer.can_read(timeout)|  File "/home/dmitry/.conda/envs/VeriFast/lib/python3.9/site-packages/redis/connection.py", line 230, in can_read|    self._read_from_socket(timeout=timeout,|  File "/home/dmitry/.conda/envs/VeriFast/lib/python3.9/site-packages/redis/connection.py", line 201, in _read_from_socket|    raise ConnectionError(SERVER_CLOSED_CONNECTION_ERROR)|redis.exceptions.ConnectionError: Connection closed by server.||During handling of the above exception, another exception occurred:||Traceback (most recent call last):|  File "/home/dmitry/.conda/envs/VeriFast/lib/python3.9/site-packages/redis/connection.py", line 559, in connect|    sock = self._connect()|  File "/home/dmitry/.conda/envs/VeriFast/lib/python3.9/site-packages/redis/connection.py", line 615, in _connect|    raise err|  File "/home/dmitry/.conda/envs/VeriFast/lib/python3.9/site-packages/redis/connection.py", line 603, in _connect|    sock.connect(socket_address)|ConnectionRefusedError: [Errno 111] Connection refused||During handling of the above exception, another exception occurred:||Traceback (most recent call last):|  File "/home/dmitry/PycharmProjects/VeriFast/./app/Background_tasks.py", line 59, in download_article|    job.save_meta()|  File "/home/dmitry/.conda/envs/VeriFast/lib/python3.9/site-packages/rq/job.py", line 679, in save_meta|    self.connection.hset(self.key, 'meta', meta)|  File "/home/dmitry/.conda/envs/VeriFast/lib/python3.9/site-packages/redis/client.py", line 3050, in hset|    return self.execute_command('HSET', name, *items)|  File "/home/dmitry/.conda/envs/VeriFast/lib/python3.9/site-packages/redis/client.py", line 898, in execute_command|    conn = self.connection or pool.get_connection(command_name, **options)|  File "/home/dmitry/.conda/envs/VeriFast/lib/python3.9/site-packages/redis/connection.py", line 1202, in get_connection|    connection.connect()|  File "/home/dmitry/.conda/envs/VeriFast/lib/python3.9/site-packages/redis/connection.py", line 563, in connect|    raise ConnectionError(self._error_message(e))|redis.exceptions.ConnectionError: Error 111 connecting to localhost:6379. Connection refused.|
'The Human Genome Browser at UCSC.';Traceback (most recent call last):|  File "/home/dmitry/PycharmProjects/VeriFast/./app/Background_tasks.py", line 34, in download_article|    xml_file_text, source = await SearcherObj(doi_or_name)|  File "/home/dmitry/PycharmProjects/VeriFast/./searcher.py", line 61, in __call__|    id_tuple = self.convert_id(crossref_meta["DOI"])|  File "/home/dmitry/PycharmProjects/VeriFast/./searcher.py", line 109, in convert_id|    print(record.pmid, record.pmcid, record.doi)|AttributeError: 'NoneType' object has no attribute 'pmid'|
'Hox cofactors in vertebrate development.';Traceback (most recent call last):|  File "/home/dmitry/.conda/envs/VeriFast/lib/python3.9/site-packages/redis/connection.py", line 1198, in get_connection|    if connection.can_read():|  File "/home/dmitry/.conda/envs/VeriFast/lib/python3.9/site-packages/redis/connection.py", line 734, in can_read|    return self._parser.can_read(timeout)|  File "/home/dmitry/.conda/envs/VeriFast/lib/python3.9/site-packages/redis/connection.py", line 321, in can_read|    return self._buffer and self._buffer.can_read(timeout)|  File "/home/dmitry/.conda/envs/VeriFast/lib/python3.9/site-packages/redis/connection.py", line 230, in can_read|    self._read_from_socket(timeout=timeout,|  File "/home/dmitry/.conda/envs/VeriFast/lib/python3.9/site-packages/redis/connection.py", line 201, in _read_from_socket|    raise ConnectionError(SERVER_CLOSED_CONNECTION_ERROR)|redis.exceptions.ConnectionError: Connection closed by server.||During handling of the above exception, another exception occurred:||Traceback (most recent call last):|  File "/home/dmitry/.conda/envs/VeriFast/lib/python3.9/site-packages/redis/connection.py", line 559, in connect|    sock = self._connect()|  File "/home/dmitry/.conda/envs/VeriFast/lib/python3.9/site-packages/redis/connection.py", line 615, in _connect|    raise err|  File "/home/dmitry/.conda/envs/VeriFast/lib/python3.9/site-packages/redis/connection.py", line 603, in _connect|    sock.connect(socket_address)|ConnectionRefusedError: [Errno 111] Connection refused||During handling of the above exception, another exception occurred:||Traceback (most recent call last):|  File "/home/dmitry/PycharmProjects/VeriFast/./app/Background_tasks.py", line 59, in download_article|    job.save_meta()|  File "/home/dmitry/.conda/envs/VeriFast/lib/python3.9/site-packages/rq/job.py", line 679, in save_meta|    self.connection.hset(self.key, 'meta', meta)|  File "/home/dmitry/.conda/envs/VeriFast/lib/python3.9/site-packages/redis/client.py", line 3050, in hset|    return self.execute_command('HSET', name, *items)|  File "/home/dmitry/.conda/envs/VeriFast/lib/python3.9/site-packages/redis/client.py", line 898, in execute_command|    conn = self.connection or pool.get_connection(command_name, **options)|  File "/home/dmitry/.conda/envs/VeriFast/lib/python3.9/site-packages/redis/connection.py", line 1202, in get_connection|    connection.connect()|  File "/home/dmitry/.conda/envs/VeriFast/lib/python3.9/site-packages/redis/connection.py", line 563, in connect|    raise ConnectionError(self._error_message(e))|redis.exceptions.ConnectionError: Error 111 connecting to localhost:6379. Connection refused.|
'Telomere shortening and telomerase reverse transcriptase expression in preinvasive bronchial lesions.';Traceback (most recent call last):|  File "/home/dmitry/PycharmProjects/VeriFast/./app/Background_tasks.py", line 34, in download_article|    xml_file_text, source = await SearcherObj(doi_or_name)|  File "/home/dmitry/PycharmProjects/VeriFast/./searcher.py", line 68, in __call__|    pmc_parsed = ET.fromstring(pmc_xml)|  File "/home/dmitry/.conda/envs/VeriFast/lib/python3.9/xml/etree/ElementTree.py", line 1347, in XML|    parser.feed(text)|TypeError: a bytes-like object is required, not 'NoneType'|
'Cutaneous cancer stem cell maintenance is dependent on beta-catenin signalling.';Traceback (most recent call last):|  File "/home/dmitry/PycharmProjects/VeriFast/./app/Background_tasks.py", line 34, in download_article|    xml_file_text, source = await SearcherObj(doi_or_name)|  File "/home/dmitry/PycharmProjects/VeriFast/./searcher.py", line 61, in __call__|    id_tuple = self.convert_id(crossref_meta["DOI"])|  File "/home/dmitry/PycharmProjects/VeriFast/./searcher.py", line 109, in convert_id|    print(record.pmid, record.pmcid, record.doi)|AttributeError: 'NoneType' object has no attribute 'pmid'|
'The molecular mechanism governing the oncogenic potential of SOX2 in breast cancer.';Traceback (most recent call last):|  File "/home/dmitry/.conda/envs/VeriFast/lib/python3.9/site-packages/redis/connection.py", line 1198, in get_connection|    if connection.can_read():|  File "/home/dmitry/.conda/envs/VeriFast/lib/python3.9/site-packages/redis/connection.py", line 734, in can_read|    return self._parser.can_read(timeout)|  File "/home/dmitry/.conda/envs/VeriFast/lib/python3.9/site-packages/redis/connection.py", line 321, in can_read|    return self._buffer and self._buffer.can_read(timeout)|  File "/home/dmitry/.conda/envs/VeriFast/lib/python3.9/site-packages/redis/connection.py", line 230, in can_read|    self._read_from_socket(timeout=timeout,|  File "/home/dmitry/.conda/envs/VeriFast/lib/python3.9/site-packages/redis/connection.py", line 201, in _read_from_socket|    raise ConnectionError(SERVER_CLOSED_CONNECTION_ERROR)|redis.exceptions.ConnectionError: Connection closed by server.||During handling of the above exception, another exception occurred:||Traceback (most recent call last):|  File "/home/dmitry/.conda/envs/VeriFast/lib/python3.9/site-packages/redis/connection.py", line 559, in connect|    sock = self._connect()|  File "/home/dmitry/.conda/envs/VeriFast/lib/python3.9/site-packages/redis/connection.py", line 615, in _connect|    raise err|  File "/home/dmitry/.conda/envs/VeriFast/lib/python3.9/site-packages/redis/connection.py", line 603, in _connect|    sock.connect(socket_address)|ConnectionRefusedError: [Errno 111] Connection refused||During handling of the above exception, another exception occurred:||Traceback (most recent call last):|  File "/home/dmitry/PycharmProjects/VeriFast/./app/Background_tasks.py", line 59, in download_article|    job.save_meta()|  File "/home/dmitry/.conda/envs/VeriFast/lib/python3.9/site-packages/rq/job.py", line 679, in save_meta|    self.connection.hset(self.key, 'meta', meta)|  File "/home/dmitry/.conda/envs/VeriFast/lib/python3.9/site-packages/redis/client.py", line 3050, in hset|    return self.execute_command('HSET', name, *items)|  File "/home/dmitry/.conda/envs/VeriFast/lib/python3.9/site-packages/redis/client.py", line 898, in execute_command|    conn = self.connection or pool.get_connection(command_name, **options)|  File "/home/dmitry/.conda/envs/VeriFast/lib/python3.9/site-packages/redis/connection.py", line 1202, in get_connection|    connection.connect()|  File "/home/dmitry/.conda/envs/VeriFast/lib/python3.9/site-packages/redis/connection.py", line 563, in connect|    raise ConnectionError(self._error_message(e))|redis.exceptions.ConnectionError: Error 111 connecting to localhost:6379. Connection refused.|
'Pairing SOX off: with partners in the regulation of embryonic development.';Traceback (most recent call last):|  File "/home/dmitry/.conda/envs/VeriFast/lib/python3.9/site-packages/redis/connection.py", line 1198, in get_connection|    if connection.can_read():|  File "/home/dmitry/.conda/envs/VeriFast/lib/python3.9/site-packages/redis/connection.py", line 734, in can_read|    return self._parser.can_read(timeout)|  File "/home/dmitry/.conda/envs/VeriFast/lib/python3.9/site-packages/redis/connection.py", line 321, in can_read|    return self._buffer and self._buffer.can_read(timeout)|  File "/home/dmitry/.conda/envs/VeriFast/lib/python3.9/site-packages/redis/connection.py", line 230, in can_read|    self._read_from_socket(timeout=timeout,|  File "/home/dmitry/.conda/envs/VeriFast/lib/python3.9/site-packages/redis/connection.py", line 201, in _read_from_socket|    raise ConnectionError(SERVER_CLOSED_CONNECTION_ERROR)|redis.exceptions.ConnectionError: Connection closed by server.||During handling of the above exception, another exception occurred:||Traceback (most recent call last):|  File "/home/dmitry/.conda/envs/VeriFast/lib/python3.9/site-packages/redis/connection.py", line 559, in connect|    sock = self._connect()|  File "/home/dmitry/.conda/envs/VeriFast/lib/python3.9/site-packages/redis/connection.py", line 615, in _connect|    raise err|  File "/home/dmitry/.conda/envs/VeriFast/lib/python3.9/site-packages/redis/connection.py", line 603, in _connect|    sock.connect(socket_address)|ConnectionRefusedError: [Errno 111] Connection refused||During handling of the above exception, another exception occurred:||Traceback (most recent call last):|  File "/home/dmitry/PycharmProjects/VeriFast/./app/Background_tasks.py", line 59, in download_article|    job.save_meta()|  File "/home/dmitry/.conda/envs/VeriFast/lib/python3.9/site-packages/rq/job.py", line 679, in save_meta|    self.connection.hset(self.key, 'meta', meta)|  File "/home/dmitry/.conda/envs/VeriFast/lib/python3.9/site-packages/redis/client.py", line 3050, in hset|    return self.execute_command('HSET', name, *items)|  File "/home/dmitry/.conda/envs/VeriFast/lib/python3.9/site-packages/redis/client.py", line 898, in execute_command|    conn = self.connection or pool.get_connection(command_name, **options)|  File "/home/dmitry/.conda/envs/VeriFast/lib/python3.9/site-packages/redis/connection.py", line 1202, in get_connection|    connection.connect()|  File "/home/dmitry/.conda/envs/VeriFast/lib/python3.9/site-packages/redis/connection.py", line 563, in connect|    raise ConnectionError(self._error_message(e))|redis.exceptions.ConnectionError: Error 111 connecting to localhost:6379. Connection refused.|
'Identification and expansion of the tumorigenic lung cancer stem cell population.';Traceback (most recent call last):|  File "/home/dmitry/PycharmProjects/VeriFast/./app/Background_tasks.py", line 34, in download_article|    xml_file_text, source = await SearcherObj(doi_or_name)|  File "/home/dmitry/PycharmProjects/VeriFast/./searcher.py", line 68, in __call__|    pmc_parsed = ET.fromstring(pmc_xml)|  File "/home/dmitry/.conda/envs/VeriFast/lib/python3.9/xml/etree/ElementTree.py", line 1347, in XML|    parser.feed(text)|TypeError: a bytes-like object is required, not 'NoneType'|
'Amplicon mapping and transcriptional analysis pinpoint cyclin L as a candidate oncogene in head and neck cancer.';Traceback (most recent call last):|  File "/home/dmitry/PycharmProjects/VeriFast/./app/Background_tasks.py", line 34, in download_article|    xml_file_text, source = await SearcherObj(doi_or_name)|  File "/home/dmitry/PycharmProjects/VeriFast/./searcher.py", line 68, in __call__|    pmc_parsed = ET.fromstring(pmc_xml)|  File "/home/dmitry/.conda/envs/VeriFast/lib/python3.9/xml/etree/ElementTree.py", line 1347, in XML|    parser.feed(text)|TypeError: a bytes-like object is required, not 'NoneType'|
'SOX2 is an amplified lineage-survival oncogene in lung and esophageal squamous cell carcinomas.';Traceback (most recent call last):|  File "/home/dmitry/.conda/envs/VeriFast/lib/python3.9/site-packages/redis/connection.py", line 1198, in get_connection|    if connection.can_read():|  File "/home/dmitry/.conda/envs/VeriFast/lib/python3.9/site-packages/redis/connection.py", line 734, in can_read|    return self._parser.can_read(timeout)|  File "/home/dmitry/.conda/envs/VeriFast/lib/python3.9/site-packages/redis/connection.py", line 321, in can_read|    return self._buffer and self._buffer.can_read(timeout)|  File "/home/dmitry/.conda/envs/VeriFast/lib/python3.9/site-packages/redis/connection.py", line 230, in can_read|    self._read_from_socket(timeout=timeout,|  File "/home/dmitry/.conda/envs/VeriFast/lib/python3.9/site-packages/redis/connection.py", line 201, in _read_from_socket|    raise ConnectionError(SERVER_CLOSED_CONNECTION_ERROR)|redis.exceptions.ConnectionError: Connection closed by server.||During handling of the above exception, another exception occurred:||Traceback (most recent call last):|  File "/home/dmitry/.conda/envs/VeriFast/lib/python3.9/site-packages/redis/connection.py", line 559, in connect|    sock = self._connect()|  File "/home/dmitry/.conda/envs/VeriFast/lib/python3.9/site-packages/redis/connection.py", line 615, in _connect|    raise err|  File "/home/dmitry/.conda/envs/VeriFast/lib/python3.9/site-packages/redis/connection.py", line 603, in _connect|    sock.connect(socket_address)|ConnectionRefusedError: [Errno 111] Connection refused||During handling of the above exception, another exception occurred:||Traceback (most recent call last):|  File "/home/dmitry/PycharmProjects/VeriFast/./app/Background_tasks.py", line 59, in download_article|    job.save_meta()|  File "/home/dmitry/.conda/envs/VeriFast/lib/python3.9/site-packages/rq/job.py", line 679, in save_meta|    self.connection.hset(self.key, 'meta', meta)|  File "/home/dmitry/.conda/envs/VeriFast/lib/python3.9/site-packages/redis/client.py", line 3050, in hset|    return self.execute_command('HSET', name, *items)|  File "/home/dmitry/.conda/envs/VeriFast/lib/python3.9/site-packages/redis/client.py", line 898, in execute_command|    conn = self.connection or pool.get_connection(command_name, **options)|  File "/home/dmitry/.conda/envs/VeriFast/lib/python3.9/site-packages/redis/connection.py", line 1202, in get_connection|    connection.connect()|  File "/home/dmitry/.conda/envs/VeriFast/lib/python3.9/site-packages/redis/connection.py", line 563, in connect|    raise ConnectionError(self._error_message(e))|redis.exceptions.ConnectionError: Error 111 connecting to localhost:6379. Connection refused.|
'Dcn1 functions as a scaffold-type E3 ligase for cullin neddylation.';Traceback (most recent call last):|  File "/home/dmitry/.conda/envs/VeriFast/lib/python3.9/site-packages/redis/connection.py", line 1198, in get_connection|    if connection.can_read():|  File "/home/dmitry/.conda/envs/VeriFast/lib/python3.9/site-packages/redis/connection.py", line 734, in can_read|    return self._parser.can_read(timeout)|  File "/home/dmitry/.conda/envs/VeriFast/lib/python3.9/site-packages/redis/connection.py", line 321, in can_read|    return self._buffer and self._buffer.can_read(timeout)|  File "/home/dmitry/.conda/envs/VeriFast/lib/python3.9/site-packages/redis/connection.py", line 230, in can_read|    self._read_from_socket(timeout=timeout,|  File "/home/dmitry/.conda/envs/VeriFast/lib/python3.9/site-packages/redis/connection.py", line 201, in _read_from_socket|    raise ConnectionError(SERVER_CLOSED_CONNECTION_ERROR)|redis.exceptions.ConnectionError: Connection closed by server.||During handling of the above exception, another exception occurred:||Traceback (most recent call last):|  File "/home/dmitry/.conda/envs/VeriFast/lib/python3.9/site-packages/redis/connection.py", line 559, in connect|    sock = self._connect()|  File "/home/dmitry/.conda/envs/VeriFast/lib/python3.9/site-packages/redis/connection.py", line 615, in _connect|    raise err|  File "/home/dmitry/.conda/envs/VeriFast/lib/python3.9/site-packages/redis/connection.py", line 603, in _connect|    sock.connect(socket_address)|ConnectionRefusedError: [Errno 111] Connection refused||During handling of the above exception, another exception occurred:||Traceback (most recent call last):|  File "/home/dmitry/PycharmProjects/VeriFast/./app/Background_tasks.py", line 59, in download_article|    job.save_meta()|  File "/home/dmitry/.conda/envs/VeriFast/lib/python3.9/site-packages/rq/job.py", line 679, in save_meta|    self.connection.hset(self.key, 'meta', meta)|  File "/home/dmitry/.conda/envs/VeriFast/lib/python3.9/site-packages/redis/client.py", line 3050, in hset|    return self.execute_command('HSET', name, *items)|  File "/home/dmitry/.conda/envs/VeriFast/lib/python3.9/site-packages/redis/client.py", line 898, in execute_command|    conn = self.connection or pool.get_connection(command_name, **options)|  File "/home/dmitry/.conda/envs/VeriFast/lib/python3.9/site-packages/redis/connection.py", line 1202, in get_connection|    connection.connect()|  File "/home/dmitry/.conda/envs/VeriFast/lib/python3.9/site-packages/redis/connection.py", line 563, in connect|    raise ConnectionError(self._error_message(e))|redis.exceptions.ConnectionError: Error 111 connecting to localhost:6379. Connection refused.|
'A third-generation lentivirus vector with a conditional packaging system.';Traceback (most recent call last):|  File "/home/dmitry/PycharmProjects/VeriFast/./app/Background_tasks.py", line 34, in download_article|    xml_file_text, source = await SearcherObj(doi_or_name)|  File "/home/dmitry/PycharmProjects/VeriFast/./searcher.py", line 67, in __call__|    pmc_xml = await self.fetch_fulltext(pmcid=id_tuple[1])|  File "/home/dmitry/PycharmProjects/VeriFast/./searcher.py", line 182, in fetch_fulltext|    pmc_data = self.ncbi_fetch(pmcid, database="pmc")|  File "/home/dmitry/PycharmProjects/VeriFast/./searcher.py", line 114, in ncbi_fetch|    handle = Entrez.efetch(db=database, id=id_input, rettype="full", retmode="xml")|  File "/home/dmitry/.conda/envs/VeriFast/lib/python3.9/site-packages/Bio/Entrez/__init__.py", line 207, in efetch|    return _open(cgi, variables, post=post)|  File "/home/dmitry/.conda/envs/VeriFast/lib/python3.9/site-packages/Bio/Entrez/__init__.py", line 606, in _open|    handle = urlopen(cgi)|  File "/home/dmitry/.conda/envs/VeriFast/lib/python3.9/urllib/request.py", line 214, in urlopen|    return opener.open(url, data, timeout)|  File "/home/dmitry/.conda/envs/VeriFast/lib/python3.9/urllib/request.py", line 523, in open|    response = meth(req, response)|  File "/home/dmitry/.conda/envs/VeriFast/lib/python3.9/urllib/request.py", line 632, in http_response|    response = self.parent.error(|  File "/home/dmitry/.conda/envs/VeriFast/lib/python3.9/urllib/request.py", line 561, in error|    return self._call_chain(*args)|  File "/home/dmitry/.conda/envs/VeriFast/lib/python3.9/urllib/request.py", line 494, in _call_chain|    result = func(*args)|  File "/home/dmitry/.conda/envs/VeriFast/lib/python3.9/urllib/request.py", line 641, in http_error_default|    raise HTTPError(req.full_url, code, msg, hdrs, fp)|urllib.error.HTTPError: HTTP Error 429: Too Many Requests|
'Overlapping 3q28 amplifications in the COMA cell line and undifferentiated primary sarcoma.';Traceback (most recent call last):|  File "/home/dmitry/PycharmProjects/VeriFast/./app/Background_tasks.py", line 39, in download_article|    json_file = Parser()(xml_file_text, source, parse_citations=True)|  File "/home/dmitry/PycharmProjects/VeriFast/./aparser.py", line 126, in __call__|    raise NotImplementedError(f"The data format `{data_format}` is not yet supported by the parser.")|NotImplementedError: The data format `Elsevier BV` is not yet supported by the parser.|
'Phosphorylation dynamics during early differentiation of human embryonic stem cells.';Traceback (most recent call last):|  File "/home/dmitry/.conda/envs/VeriFast/lib/python3.9/site-packages/redis/connection.py", line 1198, in get_connection|    if connection.can_read():|  File "/home/dmitry/.conda/envs/VeriFast/lib/python3.9/site-packages/redis/connection.py", line 734, in can_read|    return self._parser.can_read(timeout)|  File "/home/dmitry/.conda/envs/VeriFast/lib/python3.9/site-packages/redis/connection.py", line 321, in can_read|    return self._buffer and self._buffer.can_read(timeout)|  File "/home/dmitry/.conda/envs/VeriFast/lib/python3.9/site-packages/redis/connection.py", line 230, in can_read|    self._read_from_socket(timeout=timeout,|  File "/home/dmitry/.conda/envs/VeriFast/lib/python3.9/site-packages/redis/connection.py", line 201, in _read_from_socket|    raise ConnectionError(SERVER_CLOSED_CONNECTION_ERROR)|redis.exceptions.ConnectionError: Connection closed by server.||During handling of the above exception, another exception occurred:||Traceback (most recent call last):|  File "/home/dmitry/.conda/envs/VeriFast/lib/python3.9/site-packages/redis/connection.py", line 559, in connect|    sock = self._connect()|  File "/home/dmitry/.conda/envs/VeriFast/lib/python3.9/site-packages/redis/connection.py", line 615, in _connect|    raise err|  File "/home/dmitry/.conda/envs/VeriFast/lib/python3.9/site-packages/redis/connection.py", line 603, in _connect|    sock.connect(socket_address)|ConnectionRefusedError: [Errno 111] Connection refused||During handling of the above exception, another exception occurred:||Traceback (most recent call last):|  File "/home/dmitry/PycharmProjects/VeriFast/./app/Background_tasks.py", line 59, in download_article|    job.save_meta()|  File "/home/dmitry/.conda/envs/VeriFast/lib/python3.9/site-packages/rq/job.py", line 679, in save_meta|    self.connection.hset(self.key, 'meta', meta)|  File "/home/dmitry/.conda/envs/VeriFast/lib/python3.9/site-packages/redis/client.py", line 3050, in hset|    return self.execute_command('HSET', name, *items)|  File "/home/dmitry/.conda/envs/VeriFast/lib/python3.9/site-packages/redis/client.py", line 898, in execute_command|    conn = self.connection or pool.get_connection(command_name, **options)|  File "/home/dmitry/.conda/envs/VeriFast/lib/python3.9/site-packages/redis/connection.py", line 1202, in get_connection|    connection.connect()|  File "/home/dmitry/.conda/envs/VeriFast/lib/python3.9/site-packages/redis/connection.py", line 563, in connect|    raise ConnectionError(self._error_message(e))|redis.exceptions.ConnectionError: Error 111 connecting to localhost:6379. Connection refused.|
'SOX2 is frequently downregulated in gastric cancers and inhibits cell growth through cell-cycle arrest and apoptosis.';Traceback (most recent call last):|  File "/home/dmitry/PycharmProjects/VeriFast/./app/Background_tasks.py", line 34, in download_article|    xml_file_text, source = await SearcherObj(doi_or_name)|  File "/home/dmitry/PycharmProjects/VeriFast/./searcher.py", line 67, in __call__|    pmc_xml = await self.fetch_fulltext(pmcid=id_tuple[1])|  File "/home/dmitry/PycharmProjects/VeriFast/./searcher.py", line 182, in fetch_fulltext|    pmc_data = self.ncbi_fetch(pmcid, database="pmc")|  File "/home/dmitry/PycharmProjects/VeriFast/./searcher.py", line 114, in ncbi_fetch|    handle = Entrez.efetch(db=database, id=id_input, rettype="full", retmode="xml")|  File "/home/dmitry/.conda/envs/VeriFast/lib/python3.9/site-packages/Bio/Entrez/__init__.py", line 207, in efetch|    return _open(cgi, variables, post=post)|  File "/home/dmitry/.conda/envs/VeriFast/lib/python3.9/site-packages/Bio/Entrez/__init__.py", line 606, in _open|    handle = urlopen(cgi)|  File "/home/dmitry/.conda/envs/VeriFast/lib/python3.9/urllib/request.py", line 214, in urlopen|    return opener.open(url, data, timeout)|  File "/home/dmitry/.conda/envs/VeriFast/lib/python3.9/urllib/request.py", line 523, in open|    response = meth(req, response)|  File "/home/dmitry/.conda/envs/VeriFast/lib/python3.9/urllib/request.py", line 632, in http_response|    response = self.parent.error(|  File "/home/dmitry/.conda/envs/VeriFast/lib/python3.9/urllib/request.py", line 561, in error|    return self._call_chain(*args)|  File "/home/dmitry/.conda/envs/VeriFast/lib/python3.9/urllib/request.py", line 494, in _call_chain|    result = func(*args)|  File "/home/dmitry/.conda/envs/VeriFast/lib/python3.9/urllib/request.py", line 641, in http_error_default|    raise HTTPError(req.full_url, code, msg, hdrs, fp)|urllib.error.HTTPError: HTTP Error 429: Too Many Requests|
'Cancerous stem cells can arise from pediatric brain tumors.';Traceback (most recent call last):|  File "/home/dmitry/.conda/envs/VeriFast/lib/python3.9/site-packages/redis/connection.py", line 1198, in get_connection|    if connection.can_read():|  File "/home/dmitry/.conda/envs/VeriFast/lib/python3.9/site-packages/redis/connection.py", line 734, in can_read|    return self._parser.can_read(timeout)|  File "/home/dmitry/.conda/envs/VeriFast/lib/python3.9/site-packages/redis/connection.py", line 321, in can_read|    return self._buffer and self._buffer.can_read(timeout)|  File "/home/dmitry/.conda/envs/VeriFast/lib/python3.9/site-packages/redis/connection.py", line 230, in can_read|    self._read_from_socket(timeout=timeout,|  File "/home/dmitry/.conda/envs/VeriFast/lib/python3.9/site-packages/redis/connection.py", line 201, in _read_from_socket|    raise ConnectionError(SERVER_CLOSED_CONNECTION_ERROR)|redis.exceptions.ConnectionError: Connection closed by server.||During handling of the above exception, another exception occurred:||Traceback (most recent call last):|  File "/home/dmitry/.conda/envs/VeriFast/lib/python3.9/site-packages/redis/connection.py", line 559, in connect|    sock = self._connect()|  File "/home/dmitry/.conda/envs/VeriFast/lib/python3.9/site-packages/redis/connection.py", line 615, in _connect|    raise err|  File "/home/dmitry/.conda/envs/VeriFast/lib/python3.9/site-packages/redis/connection.py", line 603, in _connect|    sock.connect(socket_address)|ConnectionRefusedError: [Errno 111] Connection refused||During handling of the above exception, another exception occurred:||Traceback (most recent call last):|  File "/home/dmitry/PycharmProjects/VeriFast/./app/Background_tasks.py", line 59, in download_article|    job.save_meta()|  File "/home/dmitry/.conda/envs/VeriFast/lib/python3.9/site-packages/rq/job.py", line 679, in save_meta|    self.connection.hset(self.key, 'meta', meta)|  File "/home/dmitry/.conda/envs/VeriFast/lib/python3.9/site-packages/redis/client.py", line 3050, in hset|    return self.execute_command('HSET', name, *items)|  File "/home/dmitry/.conda/envs/VeriFast/lib/python3.9/site-packages/redis/client.py", line 898, in execute_command|    conn = self.connection or pool.get_connection(command_name, **options)|  File "/home/dmitry/.conda/envs/VeriFast/lib/python3.9/site-packages/redis/connection.py", line 1202, in get_connection|    connection.connect()|  File "/home/dmitry/.conda/envs/VeriFast/lib/python3.9/site-packages/redis/connection.py", line 563, in connect|    raise ConnectionError(self._error_message(e))|redis.exceptions.ConnectionError: Error 111 connecting to localhost:6379. Connection refused.|
'The UCSC Genome Browser Database.';Traceback (most recent call last):|  File "/home/dmitry/.conda/envs/VeriFast/lib/python3.9/site-packages/redis/connection.py", line 1198, in get_connection|    if connection.can_read():|  File "/home/dmitry/.conda/envs/VeriFast/lib/python3.9/site-packages/redis/connection.py", line 734, in can_read|    return self._parser.can_read(timeout)|  File "/home/dmitry/.conda/envs/VeriFast/lib/python3.9/site-packages/redis/connection.py", line 321, in can_read|    return self._buffer and self._buffer.can_read(timeout)|  File "/home/dmitry/.conda/envs/VeriFast/lib/python3.9/site-packages/redis/connection.py", line 230, in can_read|    self._read_from_socket(timeout=timeout,|  File "/home/dmitry/.conda/envs/VeriFast/lib/python3.9/site-packages/redis/connection.py", line 201, in _read_from_socket|    raise ConnectionError(SERVER_CLOSED_CONNECTION_ERROR)|redis.exceptions.ConnectionError: Connection closed by server.||During handling of the above exception, another exception occurred:||Traceback (most recent call last):|  File "/home/dmitry/.conda/envs/VeriFast/lib/python3.9/site-packages/redis/connection.py", line 559, in connect|    sock = self._connect()|  File "/home/dmitry/.conda/envs/VeriFast/lib/python3.9/site-packages/redis/connection.py", line 615, in _connect|    raise err|  File "/home/dmitry/.conda/envs/VeriFast/lib/python3.9/site-packages/redis/connection.py", line 603, in _connect|    sock.connect(socket_address)|ConnectionRefusedError: [Errno 111] Connection refused||During handling of the above exception, another exception occurred:||Traceback (most recent call last):|  File "/home/dmitry/PycharmProjects/VeriFast/./app/Background_tasks.py", line 59, in download_article|    job.save_meta()|  File "/home/dmitry/.conda/envs/VeriFast/lib/python3.9/site-packages/rq/job.py", line 679, in save_meta|    self.connection.hset(self.key, 'meta', meta)|  File "/home/dmitry/.conda/envs/VeriFast/lib/python3.9/site-packages/redis/client.py", line 3050, in hset|    return self.execute_command('HSET', name, *items)|  File "/home/dmitry/.conda/envs/VeriFast/lib/python3.9/site-packages/redis/client.py", line 898, in execute_command|    conn = self.connection or pool.get_connection(command_name, **options)|  File "/home/dmitry/.conda/envs/VeriFast/lib/python3.9/site-packages/redis/connection.py", line 1202, in get_connection|    connection.connect()|  File "/home/dmitry/.conda/envs/VeriFast/lib/python3.9/site-packages/redis/connection.py", line 563, in connect|    raise ConnectionError(self._error_message(e))|redis.exceptions.ConnectionError: Error 111 connecting to localhost:6379. Connection refused.|
'Identification of a subpopulation of cells with cancer stem cell properties in head and neck squamous cell carcinoma.';Traceback (most recent call last):|  File "/home/dmitry/.conda/envs/VeriFast/lib/python3.9/site-packages/redis/connection.py", line 1198, in get_connection|    if connection.can_read():|  File "/home/dmitry/.conda/envs/VeriFast/lib/python3.9/site-packages/redis/connection.py", line 734, in can_read|    return self._parser.can_read(timeout)|  File "/home/dmitry/.conda/envs/VeriFast/lib/python3.9/site-packages/redis/connection.py", line 321, in can_read|    return self._buffer and self._buffer.can_read(timeout)|  File "/home/dmitry/.conda/envs/VeriFast/lib/python3.9/site-packages/redis/connection.py", line 230, in can_read|    self._read_from_socket(timeout=timeout,|  File "/home/dmitry/.conda/envs/VeriFast/lib/python3.9/site-packages/redis/connection.py", line 201, in _read_from_socket|    raise ConnectionError(SERVER_CLOSED_CONNECTION_ERROR)|redis.exceptions.ConnectionError: Connection closed by server.||During handling of the above exception, another exception occurred:||Traceback (most recent call last):|  File "/home/dmitry/.conda/envs/VeriFast/lib/python3.9/site-packages/redis/connection.py", line 559, in connect|    sock = self._connect()|  File "/home/dmitry/.conda/envs/VeriFast/lib/python3.9/site-packages/redis/connection.py", line 615, in _connect|    raise err|  File "/home/dmitry/.conda/envs/VeriFast/lib/python3.9/site-packages/redis/connection.py", line 603, in _connect|    sock.connect(socket_address)|ConnectionRefusedError: [Errno 111] Connection refused||During handling of the above exception, another exception occurred:||Traceback (most recent call last):|  File "/home/dmitry/PycharmProjects/VeriFast/./app/Background_tasks.py", line 59, in download_article|    job.save_meta()|  File "/home/dmitry/.conda/envs/VeriFast/lib/python3.9/site-packages/rq/job.py", line 679, in save_meta|    self.connection.hset(self.key, 'meta', meta)|  File "/home/dmitry/.conda/envs/VeriFast/lib/python3.9/site-packages/redis/client.py", line 3050, in hset|    return self.execute_command('HSET', name, *items)|  File "/home/dmitry/.conda/envs/VeriFast/lib/python3.9/site-packages/redis/client.py", line 898, in execute_command|    conn = self.connection or pool.get_connection(command_name, **options)|  File "/home/dmitry/.conda/envs/VeriFast/lib/python3.9/site-packages/redis/connection.py", line 1202, in get_connection|    connection.connect()|  File "/home/dmitry/.conda/envs/VeriFast/lib/python3.9/site-packages/redis/connection.py", line 563, in connect|    raise ConnectionError(self._error_message(e))|redis.exceptions.ConnectionError: Error 111 connecting to localhost:6379. Connection refused.|
